Workbook

Sheet Roster
A1: NFL PICKS LEAGUE — ROSTER
A2: Player # | B2: Player Name | C2: Division | D2: Division Name
A3: 1 | B3: Evan Loeser | C3: A | D3: Division A
A4: 2 | B4: Chris Simmons | C4: A | D4: Division A
A5: 3 | B5: Jack Smith | C5: A | D5: Division A
A6: 4 | B6: Luke Ussery | C6: A | D6: Division A
A7: 5 | B7: Mikayla Simmons | C7: B | D7: Division B
A8: 6 | B8: Alan Loeser | C8: B | D8: Division B
A9: 7 | B9: Caleb Simmons | C9: B | D9: Division B
A10: 8 | B10: Larry Loeser | C10: B | D10: Division B
A11: 9 | B11: Daddy Michael | C11: C | D11: Division C
A12: 10 | B12: Zach Zarra | C12: C | D12: Division C
A13: 11 | B13: Jeffrey Loeser | C13: C | D13: Division C
A14: 12 | B14: Jake Andrews | C14: C | D14: Division C
A16: CURRENT WEEK: | B16: 7
A17: Div A: 1-4 | Div B: 5-8 | Div C: 9-12

Sheet Schedule
A1: WEEKS 1-6 (Inter-Division)
A2: Week 1
A3: # | B3: P# | C3: Name | D3: vs | E3: P# | F3: Name
A4: 1 | B4: 1 | C4: =VLOOKUP(B4,Roster!$A$3:$B$14,2,FALSE()) -> Evan Loeser | D4: vs | E4: 5 | F4: =VLOOKUP(E4,Roster!$A$3:$B$14,2,FALSE()) -> Mikayla Simmons
A5: 2 | B5: 2 | C5: =VLOOKUP(B5,Roster!$A$3:$B$14,2,FALSE()) -> Chris Simmons | D5: vs | E5: 6 | F5: =VLOOKUP(E5,Roster!$A$3:$B$14,2,FALSE()) -> Alan Loeser
A6: 3 | B6: 3 | C6: =VLOOKUP(B6,Roster!$A$3:$B$14,2,FALSE()) -> Jack Smith | D6: vs | E6: 9 | F6: =VLOOKUP(E6,Roster!$A$3:$B$14,2,FALSE()) -> Daddy Michael
A7: 4 | B7: 4 | C7: =VLOOKUP(B7,Roster!$A$3:$B$14,2,FALSE()) -> Luke Ussery | D7: vs | E7: 10 | F7: =VLOOKUP(E7,Roster!$A$3:$B$14,2,FALSE()) -> Zach Zarra
A8: 5 | B8: 7 | C8: =VLOOKUP(B8,Roster!$A$3:$B$14,2,FALSE()) -> Caleb Simmons | D8: vs | E8: 11 | F8: =VLOOKUP(E8,Roster!$A$3:$B$14,2,FALSE()) -> Jeffrey Loeser
A9: 6 | B9: 8 | C9: =VLOOKUP(B9,Roster!$A$3:$B$14,2,FALSE()) -> Larry Loeser | D9: vs | E9: 12 | F9: =VLOOKUP(E9,Roster!$A$3:$B$14,2,FALSE()) -> Jake Andrews
A11: Week 2
A12: # | B12: P# | C12: Name | D12: vs | E12: P# | F12: Name
A13: 1 | B13: 1 | C13: =VLOOKUP(B13,Roster!$A$3:$B$14,2,FALSE()) -> Evan Loeser | D13: vs | E13: 6 | F13: =VLOOKUP(E13,Roster!$A$3:$B$14,2,FALSE()) -> Alan Loeser
A14: 2 | B14: 2 | C14: =VLOOKUP(B14,Roster!$A$3:$B$14,2,FALSE()) -> Chris Simmons | D14: vs | E14: 5 | F14: =VLOOKUP(E14,Roster!$A$3:$B$14,2,FALSE()) -> Mikayla Simmons
A15: 3 | B15: 3 | C15: =VLOOKUP(B15,Roster!$A$3:$B$14,2,FALSE()) -> Jack Smith | D15: vs | E15: 10 | F15: =VLOOKUP(E15,Roster!$A$3:$B$14,2,FALSE()) -> Zach Zarra
A16: 4 | B16: 4 | C16: =VLOOKUP(B16,Roster!$A$3:$B$14,2,FALSE()) -> Luke Ussery | D16: vs | E16: 9 | F16: =VLOOKUP(E16,Roster!$A$3:$B$14,2,FALSE()) -> Daddy Michael
A17: 5 | B17: 7 | C17: =VLOOKUP(B17,Roster!$A$3:$B$14,2,FALSE()) -> Caleb Simmons | D17: vs | E17: 12 | F17: =VLOOKUP(E17,Roster!$A$3:$B$14,2,FALSE()) -> Jake Andrews
A18: 6 | B18: 8 | C18: =VLOOKUP(B18,Roster!$A$3:$B$14,2,FALSE()) -> Larry Loeser | D18: vs | E18: 11 | F18: =VLOOKUP(E18,Roster!$A$3:$B$14,2,FALSE()) -> Jeffrey Loeser
A20: Week 3
A21: # | B21: P# | C21: Name | D21: vs | E21: P# | F21: Name
A22: 1 | B22: 1 | C22: =VLOOKUP(B22,Roster!$A$3:$B$14,2,FALSE()) -> Evan Loeser | D22: vs | E22: 7 | F22: =VLOOKUP(E22,Roster!$A$3:$B$14,2,FALSE()) -> Caleb Simmons
A23: 2 | B23: 2 | C23: =VLOOKUP(B23,Roster!$A$3:$B$14,2,FALSE()) -> Chris Simmons | D23: vs | E23: 8 | F23: =VLOOKUP(E23,Roster!$A$3:$B$14,2,FALSE()) -> Larry Loeser
A24: 3 | B24: 3 | C24: =VLOOKUP(B24,Roster!$A$3:$B$14,2,FALSE()) -> Jack Smith | D24: vs | E24: 11 | F24: =VLOOKUP(E24,Roster!$A$3:$B$14,2,FALSE()) -> Jeffrey Loeser
A25: 4 | B25: 4 | C25: =VLOOKUP(B25,Roster!$A$3:$B$14,2,FALSE()) -> Luke Ussery | D25: vs | E25: 12 | F25: =VLOOKUP(E25,Roster!$A$3:$B$14,2,FALSE()) -> Jake Andrews
A26: 5 | B26: 5 | C26: =VLOOKUP(B26,Roster!$A$3:$B$14,2,FALSE()) -> Mikayla Simmons | D26: vs | E26: 9 | F26: =VLOOKUP(E26,Roster!$A$3:$B$14,2,FALSE()) -> Daddy Michael
A27: 6 | B27: 6 | C27: =VLOOKUP(B27,Roster!$A$3:$B$14,2,FALSE()) -> Alan Loeser | D27: vs | E27: 10 | F27: =VLOOKUP(E27,Roster!$A$3:$B$14,2,FALSE()) -> Zach Zarra
A29: Week 4
A30: # | B30: P# | C30: Name | D30: vs | E30: P# | F30: Name
A31: 1 | B31: 1 | C31: =VLOOKUP(B31,Roster!$A$3:$B$14,2,FALSE()) -> Evan Loeser | D31: vs | E31: 8 | F31: =VLOOKUP(E31,Roster!$A$3:$B$14,2,FALSE()) -> Larry Loeser
A32: 2 | B32: 2 | C32: =VLOOKUP(B32,Roster!$A$3:$B$14,2,FALSE()) -> Chris Simmons | D32: vs | E32: 7 | F32: =VLOOKUP(E32,Roster!$A$3:$B$14,2,FALSE()) -> Caleb Simmons
A33: 3 | B33: 3 | C33: =VLOOKUP(B33,Roster!$A$3:$B$14,2,FALSE()) -> Jack Smith | D33: vs | E33: 12 | F33: =VLOOKUP(E33,Roster!$A$3:$B$14,2,FALSE()) -> Jake Andrews
A34: 4 | B34: 4 | C34: =VLOOKUP(B34,Roster!$A$3:$B$14,2,FALSE()) -> Luke Ussery | D34: vs | E34: 11 | F34: =VLOOKUP(E34,Roster!$A$3:$B$14,2,FALSE()) -> Jeffrey Loeser
A35: 5 | B35: 5 | C35: =VLOOKUP(B35,Roster!$A$3:$B$14,2,FALSE()) -> Mikayla Simmons | D35: vs | E35: 10 | F35: =VLOOKUP(E35,Roster!$A$3:$B$14,2,FALSE()) -> Zach Zarra
A36: 6 | B36: 6 | C36: =VLOOKUP(B36,Roster!$A$3:$B$14,2,FALSE()) -> Alan Loeser | D36: vs | E36: 9 | F36: =VLOOKUP(E36,Roster!$A$3:$B$14,2,FALSE()) -> Daddy Michael
A38: Week 5
A39: # | B39: P# | C39: Name | D39: vs | E39: P# | F39: Name
A40: 1 | B40: 3 | C40: =VLOOKUP(B40,Roster!$A$3:$B$14,2,FALSE()) -> Jack Smith | D40: vs | E40: 5 | F40: =VLOOKUP(E40,Roster!$A$3:$B$14,2,FALSE()) -> Mikayla Simmons
A41: 2 | B41: 4 | C41: =VLOOKUP(B41,Roster!$A$3:$B$14,2,FALSE()) -> Luke Ussery | D41: vs | E41: 6 | F41: =VLOOKUP(E41,Roster!$A$3:$B$14,2,FALSE()) -> Alan Loeser
A42: 3 | B42: 1 | C42: =VLOOKUP(B42,Roster!$A$3:$B$14,2,FALSE()) -> Evan Loeser | D42: vs | E42: 11 | F42: =VLOOKUP(E42,Roster!$A$3:$B$14,2,FALSE()) -> Jeffrey Loeser
A43: 4 | B43: 2 | C43: =VLOOKUP(B43,Roster!$A$3:$B$14,2,FALSE()) -> Chris Simmons | D43: vs | E43: 12 | F43: =VLOOKUP(E43,Roster!$A$3:$B$14,2,FALSE()) -> Jake Andrews
A44: 5 | B44: 7 | C44: =VLOOKUP(B44,Roster!$A$3:$B$14,2,FALSE()) -> Caleb Simmons | D44: vs | E44: 10 | F44: =VLOOKUP(E44,Roster!$A$3:$B$14,2,FALSE()) -> Zach Zarra
...

Sheet Picks Detail
A1: PICKS DETAIL — Enter each player's ATS pick per game
A2: Enter team abbreviation (e.g. SEA, NE). Green = correct, Red = wrong.
A4: WEEK 1
A5: # | B5: Away | C5: @ | D5: Home | E5: ATS Winner | F5: Evan Loeser | G5: Chris Simmons | H5: Jack Smith | I5: Luke Ussery | J5: Mikayla Simmons | K5: Alan Loeser | L5: Caleb Simmons | M5: Larry Loeser | N5: Daddy Michael | O5: Zach Zarra | P5: Jeffrey Loeser | Q5: Jake Andrews
A6: 1 | B6: NE | C6: @ | D6: SEA | E6: ='NFL Schedule'!J3 -> NE | F6: NE | G6: SEA | H6: SEA | I6: SEA | J6: NE | K6: SEA | L6: SEA | M6: SEA | N6: NE | O6: NE | P6: SEA | Q6: NE
A7: 2 | B7: SF | C7: @ | D7: LAR | E7: ='NFL Schedule'!J4 -> SF | F7: LAR | G7: LAR | H7: LAR | I7: LAR | J7: SF | K7: LAR | L7: LAR | M7: LAR | N7: SF | O7: LAR | P7: LAR | Q7: LAR
A8: 3 | B8: CHI | C8: @ | D8: CAR | E8: ='NFL Schedule'!J5 -> CHI | F8: CHI | G8: CHI | H8: CHI | I8: CHI | J8: CHI | K8: CAR | L8: CHI | M8: CHI | N8: CAR | O8: CHI | P8: CAR | Q8: CHI
A9: 4 | B9: TB | C9: @ | D9: CIN | E9: ='NFL Schedule'!J6 -> CIN | F9: CIN | G9: TB | H9: CIN | I9: TB | J9: CIN | K9: CIN | L9: CIN | M9: CIN | N9: TB | O9: CIN | P9: CIN | Q9: TB
A10: 5 | B10: NO | C10: @ | D10: DET | E10: ='NFL Schedule'!J7 -> NO | F10: DET | G10: DET | H10: DET | I10: DET | J10: NO | K10: DET | L10: DET | M10: DET | N10: DET | O10: DET | P10: DET | Q10: DET
A11: 6 | B11: BUF | C11: @ | D11: HOU | E11: ='NFL Schedule'!J8 -> BUF | F11: HOU | G11: BUF | H11: BUF | I11: HOU | J11: BUF | K11: BUF | L11: BUF | M11: BUF | N11: BUF | O11: BUF | P11: BUF | Q11: BUF
A12: 7 | B12: BAL | C12: @ | D12: IND | E12: ='NFL Schedule'!J9 -> BAL | F12: BAL | G12: BAL | H12: BAL | I12: BAL | J12: BAL | K12: BAL | L12: BAL | M12: BAL | N12: BAL | O12: BAL | P12: BAL | Q12: BAL
A13: 8 | B13: CLE | C13: @ | D13: JAX | E13: ='NFL Schedule'!J10 -> JAX | F13: JAX | G13: JAX | H13: JAX | I13: JAX | J13: JAX | K13: JAX | L13: JAX | M13: JAX | N13: CLE | O13: JAX | P13: JAX | Q13: JAX
A14: 9 | B14: ATL | C14: @ | D14: PIT | E14: ='NFL Schedule'!J11 -> PIT | F14: ATL | G14: PIT | H14: PIT | I14: PIT | J14: ATL | K14: PIT | L14: PIT | M14: PIT | N14: PIT | O14: PIT | P14: PIT | Q14: ATL
A15: 10 | B15: NYJ | C15: @ | D15: TEN | E15: ='NFL Schedule'!J12 -> NYJ | F15: TEN | G15: TEN | H15: TEN | I15: TEN | J15: NYJ | K15: NYJ | L15: TEN | M15: TEN | N15: NYJ | O15: NYJ | P15: NYJ | Q15: TEN
A16: 11 | B16: ARI | C16: @ | D16: LAC | E16: ='NFL Schedule'!J13 -> ARI | F16: LAC | G16: LAC | H16: LAC | I16: LAC | J16: ARI | K16: LAC | L16: LAC | M16: ARI | N16: ARI | O16: LAC | P16: LAC | Q16: LAC
A17: 12 | B17: MIA | C17: @ | D17: LV | E17: ='NFL Schedule'!J14 -> LV | F17: MIA | G17: MIA | H17: LV | I17: LV | J17: MIA | K17: MIA | L17: LV | M17: LV | N17: MIA | O17: LV | P17: LV | Q17: LV
... A21: 16 | B21: DEN | C21: @ | D21: KC | E21: ='NFL Schedule'!J18 -> KC | F21: DEN | G21: KC | H21: DEN | I21: KC | J21: DEN | K21: KC | L21: DEN | M21: DEN | N21: DEN | O21: DEN | P21: DEN | Q21: KC
A22: TB | B22: MNF Total | E22: ='NFL Schedule'!E19 -> 41 | F22: 43 | G22: 50 | H22: 39 | I22: 40 | J22: 30 | K22: 42 | L22: 52 | M22: 46 | N22: 44 | O22: 34 | P22: 41 | Q22: 51
A23: WEEK 2
A24: # | B24: Away | C24: @ | D24: Home | E24: ATS Winner | F24: Evan Loeser | G24: Chris Simmons | H24: Jack Smith | I24: Luke Ussery | J24: Mikayla Simmons | K24: Alan Loeser | L24: Caleb Simmons | M24: Larry Loeser | N24: Daddy Michael | O24: Zach Zarra | P24: Jeffrey Loeser | Q24: Jake Andrews
A25: 1 | B25: DET | C25: @ | D25: BUF | E25: ='NFL Schedule'!J22 -> BUF | F25: BUF | G25: BUF | H25: DET | I25: BUF | J25: BUF | K25: BUF | L25: BUF | M25: BUF | N25: DET | O25: BUF | P25: DET | Q25: BUF
A26: 2 | B26: CAR | C26: @ | D26: ATL | E26: ='NFL Schedule'!J23 -> CAR | F26: CAR | G26: CAR | H26: CAR | I26: CAR | J26: ATL | K26: CAR | L26: CAR | M26: CAR | N26: CAR | O26: CAR | P26: CAR | Q26: CAR
A27: 3 | B27: NO | C27: @ | D27: BAL | E27: ='NFL Schedule'!J24 -> NO | F27: BAL | G27: BAL | H27: BAL | I27: BAL | J27: BAL | K27: BAL | L27: BAL | M27: BAL | N27: NO | O27: NO | P27: BAL | Q27: BAL
A28: 4 | B28: MIN | C28: @ | D28: CHI | E28: ='NFL Schedule'!J25 -> MIN | F28: MIN | G28: CHI | H28: CHI | I28: CHI | J28: CHI | K28: CHI | L28: CHI | M28: CHI | N28: MIN | O28: CHI | P28: CHI | Q28: CHI
A29: 5 | B29: CIN | C29: @ | D29: HOU | E29: ='NFL Schedule'!J26 -> CIN | F29: HOU | G29: CIN | H29: CIN | I29: CIN | J29: HOU | K29: HOU | L29: HOU | M29: HOU | N29: CIN | O29: CIN | P29: HOU | Q29: HOU
A30: 6 | B30: PIT | C30: @ | D30: NE | E30: ='NFL Schedule'!J27 -> NE | F30: PIT | G30: NE | H30: PIT | I30: PIT | J30: PIT | K30: NE | L30: NE | M30: PIT | N30: PIT | O30: NE | P30: PIT | Q30: PIT
A31: 7 | B31: GB | C31: @ | D31: NYJ | E31: ='NFL Schedule'!J28 -> NYJ | F31: GB | G31: GB | H31: NYJ | I31: NYJ | J31: GB | K31: GB | L31: GB | M31: GB | N31: GB | O31: GB | P31: GB | Q31: GB
A32: 8 | B32: CLE | C32: @ | D32: TB | E32: ='NFL Schedule'!J29 -> CLE | F32: CLE | G32: TB | H32: CLE | I32: TB | J32: TB | K32: TB | L32: TB | M32: TB | N32: CLE | O32: TB | P32: TB | Q32: TB
A33: 9 | B33: PHI | C33: @ | D33: TEN | E33: ='NFL Schedule'!J30 -> TEN | F33: PHI | G33: PHI | H33: PHI | I33: PHI | J33: PHI | K33: PHI | L33: PHI | M33: PHI | N33: PHI | O33: PHI | P33: PHI | Q33: TEN
A34: 10 | B34: JAX | C34: @ | D34: DEN | E34: ='NFL Schedule'!J31 -> DEN | F34: JAX | G34: DEN | H34: JAX | I34: JAX | J34: JAX | K34: JAX | L34: JAX | M34: JAX | N34: JAX | O34: JAX | P34: JAX | Q34: JAX
A35: 11 | B35: LV | C35: @ | D35: LAC | E35: ='NFL Schedule'!J32 -> LV | F35: LV | G35: LAC | H35: LAC | I35: LV | J35: LV | K35: LAC | L35: LAC | M35: LAC | N35: LV | O35: LAC | P35: LV | Q35: LAC
A36: 12 | B36: SEA | C36: @ | D36: ARI | E36: ='NFL Schedule'!J33 -> SEA | F36: SEA | G36: SEA | H36: SEA | I36: SEA | J36: SEA | K36: SEA | L36: SEA | M36: SEA | N36: ARI | O36: SEA | P36: SEA | Q36: SEA
... A40: 16 | B40: NYG | C40: @ | D40: LAR | E40: ='NFL Schedule'!J37 -> LAR | F40: NYG | G40: LAR | H40: NYG | I40: NYG | J40: NYG | K40: LAR | L40: LAR | M40: NYG | N40: NYG | O40: NYG | P40: LAR | Q40: NYG
A41: TB | B41: MNF Total | E41: ='NFL Schedule'!E38 -> 34 | F41: 48 | G41: 47 | H41: 42 | I41: 40 | J41: 35 | K41: 45 | L41: 52 | M41: 45 | N41: 48 | O41: 42 | P41: 48 | Q41: 51
A42: WEEK 3
A43: # | B43: Away | C43: @ | D43: Home | E43: ATS Winner | F43: Evan Loeser | G43: Chris Simmons | H43: Jack Smith | I43: Luke Ussery | J43: Mikayla Simmons | K43: Alan Loeser | L43: Caleb Simmons | M43: Larry Loeser | N43: Daddy Michael | O43: Zach Zarra | P43: Jeffrey Loeser | Q43: Jake Andrews
A44: 1 | B44: ATL | C44: @ | D44: GB | E44: ='NFL Schedule'!J41 -> ATL | F44: ATL | G44: GB | H44: ATL | J44: GB | K44: GB | L44: GB | M44: GB | N44: GB | O44: GB
A45: 2 | B45: LAC | C45: @ | D45: BUF | E45: ='NFL Schedule'!J42 -> BUF | F45: BUF | G45: BUF | H45: BUF | J45: BUF | K45: BUF | L45: BUF | M45: BUF | N45: BUF | O45: BUF | P45: BUF | Q45: BUF
A46: 3 | B46: CAR | C46: @ | D46: CLE | E46: ='NFL Schedule'!J43 -> CLE | F46: CAR | G46: CLE | H46: CAR | J46: CAR | K46: CAR | L46: CAR | M46: CAR | N46: CLE | O46: CAR | P46: CAR | Q46: CAR
A47: 4 | B47: NYJ | C47: @ | D47: DET | E47: ='NFL Schedule'!J44 -> DET | F47: DET | G47: DET | H47: DET | J47: DET | K47: DET | L47: DET | M47: DET | N47: DET | O47: DET | P47: DET | Q47: NYJ
...

Sheet NFL Schedule
A1: WEEK 1
A2: Wk | B2: Day/Date | C2: Time | D2: Away | E2: Away Sc | F2: Home | G2: Home Sc | H2: Spread | I2: Winner | J2: ATS
A3: 1 | B3: Wed Sep 9 | C3: 8:20 PM | D3: NE | E3: 10 | F3: SEA | G3: 13 | H3: 3.5 | I3: =IF(OR(E3="",G3=""),"",IF(E3>G3,D3,IF(G3>E3,F3,"TIE"))) -> SEA | J3: =IF(OR(E3="",G3="",H3=""),"",IF(E3+H3>G3,D3,IF(E3+H3<G3,F3,"PUSH"))) -> NE
A4: 1 | B4: Thu Sep 10 | C4: 8:35 PM | D4: SF | E4: 27 | F4: LAR | G4: 7 | H4: 3.5 | I4: =IF(OR(E4="",G4=""),"",IF(E4>G4,D4,IF(G4>E4,F4,"TIE"))) -> SF | J4: =IF(OR(E4="",G4="",H4=""),"",IF(E4+H4>G4,D4,IF(E4+H4<G4,F4,"PUSH"))) -> SF
A5: 1 | B5: Sun Sep 13 | C5: 1:00 PM | D5: CHI | E5: 59 | F5: CAR | G5: 37 | H5: -2.5 | I5: =IF(OR(E5="",G5=""),"",IF(E5>G5,D5,IF(G5>E5,F5,"TIE"))) -> CHI | J5: =IF(OR(E5="",G5="",H5=""),"",IF(E5+H5>G5,D5,IF(E5+H5<G5,F5,"PUSH"))) -> CHI
A6: 1 | B6: Sun Sep 13 | C6: 1:00 PM | D6: TB | E6: 27 | F6: CIN | G6: 33 | H6: 3.5 | I6: =IF(OR(E6="",G6=""),"",IF(E6>G6,D6,IF(G6>E6,F6,"TIE"))) -> CIN | J6: =IF(OR(E6="",G6="",H6=""),"",IF(E6+H6>G6,D6,IF(E6+H6<G6,F6,"PUSH"))) -> CIN
A7: 1 | B7: Sun Sep 13 | C7: 1:00 PM | D7: NO | E7: 30 | F7: DET | G7: 31 | H7: 7.5 | I7: =IF(OR(E7="",G7=""),"",IF(E7>G7,D7,IF(G7>E7,F7,"TIE"))) -> DET | J7: =IF(OR(E7="",G7="",H7=""),"",IF(E7+H7>G7,D7,IF(E7+H7<G7,F7,"PUSH"))) -> NO
A8: 1 | B8: Sun Sep 13 | C8: 1:00 PM | D8: BUF | E8: 36 | F8: HOU | G8: 31 | H8: 1.5 | I8: =IF(OR(E8="",G8=""),"",IF(E8>G8,D8,IF(G8>E8,F8,"TIE"))) -> BUF | J8: =IF(OR(E8="",G8="",H8=""),"",IF(E8+H8>G8,D8,IF(E8+H8<G8,F8,"PUSH"))) -> BUF
A9: 1 | B9: Sun Sep 13 | C9: 1:00 PM | D9: BAL | E9: 41 | F9: IND | G9: 23 | H9: -3.5 | I9: =IF(OR(E9="",G9=""),"",IF(E9>G9,D9,IF(G9>E9,F9,"TIE"))) -> BAL | J9: =IF(OR(E9="",G9="",H9=""),"",IF(E9+H9>G9,D9,IF(E9+H9<G9,F9,"PUSH"))) -> BAL
A10: 1 | B10: Sun Sep 13 | C10: 1:00 PM | D10: CLE | E10: 10 | F10: JAX | G10: 34 | H10: 7.5 | I10: =IF(OR(E10="",G10=""),"",IF(E10>G10,D10,IF(G10>E10,F10,"TIE"))) -> JAX | J10: =IF(OR(E10="",G10="",H10=""),"",IF(E10+H10>G10,D10,IF(E10+H10<G10,F10,"PUSH"))) -> JAX
A11: 1 | B11: Sun Sep 13 | C11: 1:00 PM | D11: ATL | E11: 13 | F11: PIT | G11: 20 | H11: 3.5 | I11: =IF(OR(E11="",G11=""),"",IF(E11>G11,D11,IF(G11>E11,F11,"TIE"))) -> PIT | J11: =IF(OR(E11="",G11="",H11=""),"",IF(E11+H11>G11,D11,IF(E11+H11<G11,F11,"PUSH"))) -> PIT
A12: 1 | B12: Sun Sep 13 | C12: 1:00 PM | D12: NYJ | E12: 23 | F12: TEN | G12: 10 | H12: 2.5 | I12: =IF(OR(E12="",G12=""),"",IF(E12>G12,D12,IF(G12>E12,F12,"TIE"))) -> NYJ | J12: =IF(OR(E12="",G12="",H12=""),"",IF(E12+H12>G12,D12,IF(E12+H12<G12,F12,"PUSH"))) -> NYJ
A13: 1 | B13: Sun Sep 13 | C13: 4:25 PM | D13: ARI | E13: 26 | F13: LAC | G13: 14 | H13: 10.5 | I13: =IF(OR(E13="",G13=""),"",IF(E13>G13,D13,IF(G13>E13,F13,"TIE"))) -> ARI | J13: =IF(OR(E13="",G13="",H13=""),"",IF(E13+H13>G13,D13,IF(E13+H13<G13,F13,"PUSH"))) -> ARI
A14: 1 | B14: Sun Sep 13 | C14: 4:25 PM | D14: MIA | E14: 13 | F14: LV | G14: 27 | H14: 3.5 | I14: =IF(OR(E14="",G14=""),"",IF(E14>G14,D14,IF(G14>E14,F14,"TIE"))) -> LV | J14: =IF(OR(E14="",G14="",H14=""),"",IF(E14+H14>G14,D14,IF(E14+H14<G14,F14,"PUSH"))) -> LV
... A18: 1 | B18: Mon Sep 14 | C18: 8:15 PM | D18: DEN | E18: 10 | F18: KC | G18: 31 | H18: 2.5 | I18: =IF(OR(E18="",G18=""),"",IF(E18>G18,D18,IF(G18>E18,F18,"TIE"))) -> KC | J18: =IF(OR(E18="",G18="",H18=""),"",IF(E18+H18>G18,D18,IF(E18+H18<G18,F18,"PUSH"))) -> KC
D19: MNF Total | E19: =IF(AND(E18<>"",G18<>""),E18+G18,"") -> 41
A20: WEEK 2
A21: Wk | B21: Day/Date | C21: Time | D21: Away | E21: Away Sc | F21: Home | G21: Home Sc | H21: Spread | I21: Winner | J21: ATS
A22: 2 | B22: Thu Sep 17 | C22: 8:15 PM | D22: DET | E22: 31 | F22: BUF | G22: 41 | H22: 4.5 | I22: =IF(OR(E22="",G22=""),"",IF(E22>G22,D22,IF(G22>E22,F22,"TIE"))) -> BUF | J22: =IF(OR(E22="",G22="",H22=""),"",IF(E22+H22>G22,D22,IF(E22+H22<G22,F22,"PUSH"))) -> BUF
A23: 2 | B23: Sun Sep 20 | C23: 1:00 PM | D23: CAR | E23: 34 | F23: ATL | G23: 3 | H23: -1.5 | I23: =IF(OR(E23="",G23=""),"",IF(E23>G23,D23,IF(G23>E23,F23,"TIE"))) -> CAR | J23: =IF(OR(E23="",G23="",H23=""),"",IF(E23+H23>G23,D23,IF(E23+H23<G23,F23,"PUSH"))) -> CAR
A24: 2 | B24: Sun Sep 20 | C24: 1:00 PM | D24: NO | E24: 24 | F24: BAL | G24: 17 | H24: 8.5 | I24: =IF(OR(E24="",G24=""),"",IF(E24>G24,D24,IF(G24>E24,F24,"TIE"))) -> NO | J24: =IF(OR(E24="",G24="",H24=""),"",IF(E24+H24>G24,D24,IF(E24+H24<G24,F24,"PUSH"))) -> NO
A25: 2 | B25: Sun Sep 20 | C25: 1:00 PM | D25: MIN | E25: 9 | F25: CHI | G25: 3 | H25: 5.5 | I25: =IF(OR(E25="",G25=""),"",IF(E25>G25,D25,IF(G25>E25,F25,"TIE"))) -> MIN | J25: =IF(OR(E25="",G25="",H25=""),"",IF(E25+H25>G25,D25,IF(E25+H25<G25,F25,"PUSH"))) -> MIN
A26: 2 | B26: Sun Sep 20 | C26: 1:00 PM | D26: CIN | E26: 20 | F26: HOU | G26: 6 | H26: 2.5 | I26: =IF(OR(E26="",G26=""),"",IF(E26>G26,D26,IF(G26>E26,F26,"TIE"))) -> CIN | J26: =IF(OR(E26="",G26="",H26=""),"",IF(E26+H26>G26,D26,IF(E26+H26<G26,F26,"PUSH"))) -> CIN
A27: 2 | B27: Sun Sep 20 | C27: 1:00 PM | D27: PIT | E27: 3 | F27: NE | G27: 20 | H27: 5.5 | I27: =IF(OR(E27="",G27=""),"",IF(E27>G27,D27,IF(G27>E27,F27,"TIE"))) -> NE | J27: =IF(OR(E27="",G27="",H27=""),"",IF(E27+H27>G27,D27,IF(E27+H27<G27,F27,"PUSH"))) -> NE
A28: 2 | B28: Sun Sep 20 | C28: 1:00 PM | D28: GB | E28: 20 | F28: NYJ | G28: 17 | H28: -3.5 | I28: =IF(OR(E28="",G28=""),"",IF(E28>G28,D28,IF(G28>E28,F28,"TIE"))) -> GB | J28: =IF(OR(E28="",G28="",H28=""),"",IF(E28+H28>G28,D28,IF(E28+H28<G28,F28,"PUSH"))) -> NYJ
A29: 2 | B29: Sun Sep 20 | C29: 1:00 PM | D29: CLE | E29: 23 | F29: TB | G29: 19 | H29: 8.5 | I29: =IF(OR(E29="",G29=""),"",IF(E29>G29,D29,IF(G29>E29,F29,"TIE"))) -> CLE | J29: =IF(OR(E29="",G29="",H29=""),"",IF(E29+H29>G29,D29,IF(E29+H29<G29,F29,"PUSH"))) -> CLE
A30: 2 | B30: Sun Sep 20 | C30: 1:00 PM | D30: PHI | E30: 24 | F30: TEN | G30: 20 | H30: -7.5 | I30: =IF(OR(E30="",G30=""),"",IF(E30>G30,D30,IF(G30>E30,F30,"TIE"))) -> PHI | J30: =IF(OR(E30="",G30="",H30=""),"",IF(E30+H30>G30,D30,IF(E30+H30<G30,F30,"PUSH"))) -> TEN
A31: 2 | B31: Sun Sep 20 | C31: 4:05 PM | D31: JAX | E31: 13 | F31: DEN | G31: 20 | H31: 2.5 | I31: =IF(OR(E31="",G31=""),"",IF(E31>G31,D31,IF(G31>E31,F31,"TIE"))) -> DEN | J31: =IF(OR(E31="",G31="",H31=""),"",IF(E31+H31>G31,D31,IF(E31+H31<G31,F31,"PUSH"))) -> DEN
A32: 2 | B32: Sun Sep 20 | C32: 4:05 PM | D32: LV | E32: 26 | F32: LAC | G32: 14 | H32: 6.5 | I32: =IF(OR(E32="",G32=""),"",IF(E32>G32,D32,IF(G32>E32,F32,"TIE"))) -> LV | J32: =IF(OR(E32="",G32="",H32=""),"",IF(E32+H32>G32,D32,IF(E32+H32<G32,F32,"PUSH"))) -> LV
A33: 2 | B33: Sun Sep 20 | C33: 4:25 PM | D33: SEA | E33: 31 | F33: ARI | G33: 7 | H33: -3.5 | I33: =IF(OR(E33="",G33=""),"",IF(E33>G33,D33,IF(G33>E33,F33,"TIE"))) -> SEA | J33: =IF(OR(E33="",G33="",H33=""),"",IF(E33+H33>G33,D33,IF(E33+H33<G33,F33,"PUSH"))) -> SEA
... A37: 2 | B37: Mon Sep 21 | C37: 8:15 PM | D37: NYG | E37: 6 | F37: LAR | G37: 28 | H37: 7.5 | I37: =IF(OR(E37="",G37=""),"",IF(E37>G37,D37,IF(G37>E37,F37,"TIE"))) -> LAR | J37: =IF(OR(E37="",G37="",H37=""),"",IF(E37+H37>G37,D37,IF(E37+H37<G37,F37,"PUSH"))) -> LAR
D38: MNF Total | E38: =IF(AND(E37<>"",G37<>""),E37+G37,"") -> 34
A39: WEEK 3
A40: Wk | B40: Day/Date | C40: Time | D40: Away | E40: Away Sc | F40: Home | G40: Home Sc | H40: Spread | I40: Winner | J40: ATS
A41: 3 | B41: Thu Sep 24 | C41: 8:15 PM | D41: ATL | E41: 35 | F41: GB | G41: 14 | H41: 6.5 | I41: =IF(OR(E41="",G41=""),"",IF(E41>G41,D41,IF(G41>E41,F41,"TIE"))) -> ATL | J41: =IF(OR(E41="",G41="",H41=""),"",IF(E41+H41>G41,D41,IF(E41+H41<G41,F41,"PUSH"))) -> ATL
A42: 3 | B42: Sun Sep 27 | C42: 1:00 PM | D42: LAC | E42: 16 | F42: BUF | G42: 24 | H42: 7.5 | I42: =IF(OR(E42="",G42=""),"",IF(E42>G42,D42,IF(G42>E42,F42,"TIE"))) -> BUF | J42: =IF(OR(E42="",G42="",H42=""),"",IF(E42+H42>G42,D42,IF(E42+H42<G42,F42,"PUSH"))) -> BUF
A43: 3 | B43: Sun Sep 27 | C43: 1:00 PM | D43: CAR | E43: 18 | F43: CLE | G43: 21 | H43: -2.5 | I43: =IF(OR(E43="",G43=""),"",IF(E43>G43,D43,IF(G43>E43,F43,"TIE"))) -> CLE | J43: =IF(OR(E43="",G43="",H43=""),"",IF(E43+H43>G43,D43,IF(E43+H43<G43,F43,"PUSH"))) -> CLE
A44: 3 | B44: Sun Sep 27 | C44: 1:00 PM | D44: NYJ | E44: 24 | F44: DET | G44: 31 | H44: 6.5 | I44: =IF(OR(E44="",G44=""),"",IF(E44>G44,D44,IF(G44>E44,F44,"TIE"))) -> DET | J44: =IF(OR(E44="",G44="",H44=""),"",IF(E44+H44>G44,D44,IF(E44+H44<G44,F44,"PUSH"))) -> DET
A45: 3 | B45: Sun Sep 27 | C45: 1:00 PM | D45: HOU | E45: 17 | F45: IND | G45: 19 | H45: -2.5 | I45: =IF(OR(E45="",G45=""),"",IF(E45>G45,D45,IF(G45>E45,F45,"TIE"))) -> IND | J45: =IF(OR(E45="",G45="",H45=""),"",IF(E45+H45>G45,D45,IF(E45+H45<G45,F45,"PUSH"))) -> IND
A46: 3 | B46: Sun Sep 27 | C46: 1:00 PM | D46: KC | E46: 24 | F46: MIA | G46: 10 | H46: -11.5 | I46: =IF(OR(E46="",G46=""),"",IF(E46>G46,D46,IF(G46>E46,F46,"TIE"))) -> KC | J46: =IF(OR(E46="",G46="",H46=""),"",IF(E46+H46>G46,D46,IF(E46+H46<G46,F46,"PUSH"))) -> KC
...

Sheet Wk 1-6 Input
A1: WEEKS 1-6 — WEEKLY INPUT
A2: Enter correct picks. H2H auto-calculated.
A4: WEEK 1
A5: Player # | B5: Player Name | C5: Correct Picks | D5: H2H Opp | E5: Opp Picks | F5: H2H Result | G5: H2H Pts | H5: Pick Pts | I5: Week Total
A6: 1 | B6: =Roster!B3 -> Evan Loeser | C6: =SUMPRODUCT(('Picks Detail'!F6:F21<>"")*('Picks Detail'!E6:E21<>"")*('Picks Detail'!F6:F21='Picks Detail'!E6:E21)) -> 5 | D6: 5 | E6: =IFERROR(INDEX(C$6:C$17,MATCH(5,A$6:A$17,0)),0) -> 10 | F6: =IF(C6=0,"-",IF(C6>E6,"W",IF(C6<E6,"L",IF(AND('Picks Detail'!E22<>"",INDEX('Picks Detail'!F22:Q22,1,A6)<>"",INDEX('Picks Detail'!F22:Q22,1,D6)<>""),IF(ABS(INDEX('Picks Detail'!F22:Q22,1,A6)-'Picks Detail'!E22)<ABS(INDEX('Picks Detail'!F22:Q22,1,D6)-'Picks Detail'!E22),"W",IF(ABS(INDEX('Picks Detail'!F22:Q22,1,A6)-'Picks Detail'!E22)>ABS(INDEX('Picks Detail'!F22:Q22,1,D6)-'Picks Detail'!E22),"L","T")),"T")))) -> L | G6: =IF(F6="W",6,IF(F6="T",3,0)) -> 0 | H6: =IF(C6="",0,C6) -> 5 | I6: =G6+H6 -> 5
A7: 2 | B7: =Roster!B4 -> Chris Simmons | C7: =SUMPRODUCT(('Picks Detail'!G6:G21<>"")*('Picks Detail'!E6:E21<>"")*('Picks Detail'!G6:G21='Picks Detail'!E6:E21)) -> 7 | D7: 6 | E7: =IFERROR(INDEX(C$6:C$17,MATCH(6,A$6:A$17,0)),0) -> 7 | F7: =IF(C7=0,"-",IF(C7>E7,"W",IF(C7<E7,"L",IF(AND('Picks Detail'!E22<>"",INDEX('Picks Detail'!F22:Q22,1,A7)<>"",INDEX('Picks Detail'!F22:Q22,1,D7)<>""),IF(ABS(INDEX('Picks Detail'!F22:Q22,1,A7)-'Picks Detail'!E22)<ABS(INDEX('Picks Detail'!F22:Q22,1,D7)-'Picks Detail'!E22),"W",IF(ABS(INDEX('Picks Detail'!F22:Q22,1,A7)-'Picks Detail'!E22)>ABS(INDEX('Picks Detail'!F22:Q22,1,D7)-'Picks Detail'!E22),"L","T")),"T")))) -> L | G7: =IF(F7="W",6,IF(F7="T",3,0)) -> 0 | H7: =IF(C7="",0,C7) -> 7 | I7: =G7+H7 -> 7
A8: 3 | B8: =Roster!B5 -> Jack Smith | C8: =SUMPRODUCT(('Picks Detail'!H6:H21<>"")*('Picks Detail'!E6:E21<>"")*('Picks Detail'!H6:H21='Picks Detail'!E6:E21)) -> 8 | D8: 9 | E8: =IFERROR(INDEX(C$6:C$17,MATCH(9,A$6:A$17,0)),0) -> 8 | F8: =IF(C8=0,"-",IF(C8>E8,"W",IF(C8<E8,"L",IF(AND('Picks Detail'!E22<>"",INDEX('Picks Detail'!F22:Q22,1,A8)<>"",INDEX('Picks Detail'!F22:Q22,1,D8)<>""),IF(ABS(INDEX('Picks Detail'!F22:Q22,1,A8)-'Picks Detail'!E22)<ABS(INDEX('Picks Detail'!F22:Q22,1,D8)-'Picks Detail'!E22),"W",IF(ABS(INDEX('Picks Detail'!F22:Q22,1,A8)-'Picks Detail'!E22)>ABS(INDEX('Picks Detail'!F22:Q22,1,D8)-'Picks Detail'!E22),"L","T")),"T")))) -> W | G8: =IF(F8="W",6,IF(F8="T",3,0)) -> 6 | H8: =IF(C8="",0,C8) -> 8 | I8: =G8+H8 -> 14
A9: 4 | B9: =Roster!B6 -> Luke Ussery | C9: =SUMPRODUCT(('Picks Detail'!I6:I21<>"")*('Picks Detail'!E6:E21<>"")*('Picks Detail'!I6:I21='Picks Detail'!E6:E21)) -> 6 | D9: 10 | E9: =IFERROR(INDEX(C$6:C$17,MATCH(10,A$6:A$17,0)),0) -> 11 | F9: =IF(C9=0,"-",IF(C9>E9,"W",IF(C9<E9,"L",IF(AND('Picks Detail'!E22<>"",INDEX('Picks Detail'!F22:Q22,1,A9)<>"",INDEX('Picks Detail'!F22:Q22,1,D9)<>""),IF(ABS(INDEX('Picks Detail'!F22:Q22,1,A9)-'Picks Detail'!E22)<ABS(INDEX('Picks Detail'!F22:Q22,1,D9)-'Picks Detail'!E22),"W",IF(ABS(INDEX('Picks Detail'!F22:Q22,1,A9)-'Picks Detail'!E22)>ABS(INDEX('Picks Detail'!F22:Q22,1,D9)-'Picks Detail'!E22),"L","T")),"T")))) -> L | G9: =IF(F9="W",6,IF(F9="T",3,0)) -> 0 | H9: =IF(C9="",0,C9) -> 6 | I9: =G9+H9 -> 6
A10: 5 | B10: =Roster!B7 -> Mikayla Simmons | C10: =SUMPRODUCT(('Picks Detail'!J6:J21<>"")*('Picks Detail'!E6:E21<>"")*('Picks Detail'!J6:J21='Picks Detail'!E6:E21)) -> 10 | D10: 1 | E10: =IFERROR(INDEX(C$6:C$17,MATCH(1,A$6:A$17,0)),0) -> 5 | F10: =IF(C10=0,"-",IF(C10>E10,"W",IF(C10<E10,"L",IF(AND('Picks Detail'!E22<>"",INDEX('Picks Detail'!F22:Q22,1,A10)<>"",INDEX('Picks Detail'!F22:Q22,1,D10)<>""),IF(ABS(INDEX('Picks Detail'!F22:Q22,1,A10)-'Picks Detail'!E22)<ABS(INDEX('Picks Detail'!F22:Q22,1,D10)-'Picks Detail'!E22),"W",IF(ABS(INDEX('Picks Detail'!F22:Q22,1,A10)-'Picks Detail'!E22)>ABS(INDEX('Picks Detail'!F22:Q22,1,D10)-'Picks Detail'!E22),"L","T")),"T")))) -> W | G10: =IF(F10="W",6,IF(F10="T",3,0)) -> 6 | H10: =IF(C10="",0,C10) -> 10 | I10: =G10+H10 -> 16
A11: 6 | B11: =Roster!B8 -> Alan Loeser | C11: =SUMPRODUCT(('Picks Detail'!K6:K21<>"")*('Picks Detail'!E6:E21<>"")*('Picks Detail'!K6:K21='Picks Detail'!E6:E21)) -> 7 | D11: 2 | E11: =IFERROR(INDEX(C$6:C$17,MATCH(2,A$6:A$17,0)),0) -> 7 | F11: =IF(C11=0,"-",IF(C11>E11,"W",IF(C11<E11,"L",IF(AND('Picks Detail'!E22<>"",INDEX('Picks Detail'!F22:Q22,1,A11)<>"",INDEX('Picks Detail'!F22:Q22,1,D11)<>""),IF(ABS(INDEX('Picks Detail'!F22:Q22,1,A11)-'Picks Detail'!E22)<ABS(INDEX('Picks Detail'!F22:Q22,1,D11)-'Picks Detail'!E22),"W",IF(ABS(INDEX('Picks Detail'!F22:Q22,1,A11)-'Picks Detail'!E22)>ABS(INDEX('Picks Detail'!F22:Q22,1,D11)-'Picks Detail'!E22),"L","T")),"T")))) -> W | G11: =IF(F11="W",6,IF(F11="T",3,0)) -> 6 | H11: =IF(C11="",0,C11) -> 7 | I11: =G11+H11 -> 13
A12: 7 | B12: =Roster!B9 -> Caleb Simmons | C12: =SUMPRODUCT(('Picks Detail'!L6:L21<>"")*('Picks Detail'!E6:E21<>"")*('Picks Detail'!L6:L21='Picks Detail'!E6:E21)) -> 7 | D12: 11 | E12: =IFERROR(INDEX(C$6:C$17,MATCH(11,A$6:A$17,0)),0) -> 10 | F12: =IF(C12=0,"-",IF(C12>E12,"W",IF(C12<E12,"L",IF(AND('Picks Detail'!E22<>"",INDEX('Picks Detail'!F22:Q22,1,A12)<>"",INDEX('Picks Detail'!F22:Q22,1,D12)<>""),IF(ABS(INDEX('Picks Detail'!F22:Q22,1,A12)-'Picks Detail'!E22)<ABS(INDEX('Picks Detail'!F22:Q22,1,D12)-'Picks Detail'!E22),"W",IF(ABS(INDEX('Picks Detail'!F22:Q22,1,A12)-'Picks Detail'!E22)>ABS(INDEX('Picks Detail'!F22:Q22,1,D12)-'Picks Detail'!E22),"L","T")),"T")))) -> L | G12: =IF(F12="W",6,IF(F12="T",3,0)) -> 0 | H12: =IF(C12="",0,C12) -> 7 | I12: =G12+H12 -> 7
A13: 8 | B13: =Roster!B10 -> Larry Loeser | C13: =SUMPRODUCT(('Picks Detail'!M6:M21<>"")*('Picks Detail'!E6:E21<>"")*('Picks Detail'!M6:M21='Picks Detail'!E6:E21)) -> 8 | D13: 12 | E13: =IFERROR(INDEX(C$6:C$17,MATCH(12,A$6:A$17,0)),0) -> 9 | F13: =IF(C13=0,"-",IF(C13>E13,"W",IF(C13<E13,"L",IF(AND('Picks Detail'!E22<>"",INDEX('Picks Detail'!F22:Q22,1,A13)<>"",INDEX('Picks Detail'!F22:Q22,1,D13)<>""),IF(ABS(INDEX('Picks Detail'!F22:Q22,1,A13)-'Picks Detail'!E22)<ABS(INDEX('Picks Detail'!F22:Q22,1,D13)-'Picks Detail'!E22),"W",IF(ABS(INDEX('Picks Detail'!F22:Q22,1,A13)-'Picks Detail'!E22)>ABS(INDEX('Picks Detail'!F22:Q22,1,D13)-'Picks Detail'!E22),"L","T")),"T")))) -> L | G13: =IF(F13="W",6,IF(F13="T",3,0)) -> 0 | H13: =IF(C13="",0,C13) -> 8 | I13: =G13+H13 -> 8
A14: 9 | B14: =Roster!B11 -> Daddy Michael | C14: =SUMPRODUCT(('Picks Detail'!N6:N21<>"")*('Picks Detail'!E6:E21<>"")*('Picks Detail'!N6:N21='Picks Detail'!E6:E21)) -> 8 | D14: 3 | E14: =IFERROR(INDEX(C$6:C$17,MATCH(3,A$6:A$17,0)),0) -> 8 | F14: =IF(C14=0,"-",IF(C14>E14,"W",IF(C14<E14,"L",IF(AND('Picks Detail'!E22<>"",INDEX('Picks Detail'!F22:Q22,1,A14)<>"",INDEX('Picks Detail'!F22:Q22,1,D14)<>""),IF(ABS(INDEX('Picks Detail'!F22:Q22,1,A14)-'Picks Detail'!E22)<ABS(INDEX('Picks Detail'!F22:Q22,1,D14)-'Picks Detail'!E22),"W",IF(ABS(INDEX('Picks Detail'!F22:Q22,1,A14)-'Picks Detail'!E22)>ABS(INDEX('Picks Detail'!F22:Q22,1,D14)-'Picks Detail'!E22),"L","T")),"T")))) -> L | G14: =IF(F14="W",6,IF(F14="T",3,0)) -> 0 | H14: =IF(C14="",0,C14) -> 8 | I14: =G14+H14 -> 8
A15: 10 | B15: =Roster!B12 -> Zach Zarra | C15: =SUMPRODUCT(('Picks Detail'!O6:O21<>"")*('Picks Detail'!E6:E21<>"")*('Picks Detail'!O6:O21='Picks Detail'!E6:E21)) -> 11 | D15: 4 | E15: =IFERROR(INDEX(C$6:C$17,MATCH(4,A$6:A$17,0)),0) -> 6 | F15: =IF(C15=0,"-",IF(C15>E15,"W",IF(C15<E15,"L",IF(AND('Picks Detail'!E22<>"",INDEX('Picks Detail'!F22:Q22,1,A15)<>"",INDEX('Picks Detail'!F22:Q22,1,D15)<>""),IF(ABS(INDEX('Picks Detail'!F22:Q22,1,A15)-'Picks Detail'!E22)<ABS(INDEX('Picks Detail'!F22:Q22,1,D15)-'Picks Detail'!E22),"W",IF(ABS(INDEX('Picks Detail'!F22:Q22,1,A15)-'Picks Detail'!E22)>ABS(INDEX('Picks Detail'!F22:Q22,1,D15)-'Picks Detail'!E22),"L","T")),"T")))) -> W | G15: =IF(F15="W",6,IF(F15="T",3,0)) -> 6 | H15: =IF(C15="",0,C15) -> 11 | I15: =G15+H15 -> 17
A16: 11 | B16: =Roster!B13 -> Jeffrey Loeser | C16: =SUMPRODUCT(('Picks Detail'!P6:P21<>"")*('Picks Detail'!E6:E21<>"")*('Picks Detail'!P6:P21='Picks Detail'!E6:E21)) -> 10 | D16: 7 | E16: =IFERROR(INDEX(C$6:C$17,MATCH(7,A$6:A$17,0)),0) -> 7 | F16: =IF(C16=0,"-",IF(C16>E16,"W",IF(C16<E16,"L",IF(AND('Picks Detail'!E22<>"",INDEX('Picks Detail'!F22:Q22,1,A16)<>"",INDEX('Picks Detail'!F22:Q22,1,D16)<>""),IF(ABS(INDEX('Picks Detail'!F22:Q22,1,A16)-'Picks Detail'!E22)<ABS(INDEX('Picks Detail'!F22:Q22,1,D16)-'Picks Detail'!E22),"W",IF(ABS(INDEX('Picks Detail'!F22:Q22,1,A16)-'Picks Detail'!E22)>ABS(INDEX('Picks Detail'!F22:Q22,1,D16)-'Picks Detail'!E22),"L","T")),"T")))) -> W | G16: =IF(F16="W",6,IF(F16="T",3,0)) -> 6 | H16: =IF(C16="",0,C16) -> 10 | I16: =G16+H16 -> 16
A17: 12 | B17: =Roster!B14 -> Jake Andrews | C17: =SUMPRODUCT(('Picks Detail'!Q6:Q21<>"")*('Picks Detail'!E6:E21<>"")*('Picks Detail'!Q6:Q21='Picks Detail'!E6:E21)) -> 9 | D17: 8 | E17: =IFERROR(INDEX(C$6:C$17,MATCH(8,A$6:A$17,0)),0) -> 8 | F17: =IF(C17=0,"-",IF(C17>E17,"W",IF(C17<E17,"L",IF(AND('Picks Detail'!E22<>"",INDEX('Picks Detail'!F22:Q22,1,A17)<>"",INDEX('Picks Detail'!F22:Q22,1,D17)<>""),IF(ABS(INDEX('Picks Detail'!F22:Q22,1,A17)-'Picks Detail'!E22)<ABS(INDEX('Picks Detail'!F22:Q22,1,D17)-'Picks Detail'!E22),"W",IF(ABS(INDEX('Picks Detail'!F22:Q22,1,A17)-'Picks Detail'!E22)>ABS(INDEX('Picks Detail'!F22:Q22,1,D17)-'Picks Detail'!E22),"L","T")),"T")))) -> W | G17: =IF(F17="W",6,IF(F17="T",3,0)) -> 6 | H17: =IF(C17="",0,C17) -> 9 | I17: =G17+H17 -> 15
A19: WEEK 2
A20: Player # | B20: Player Name | C20: Correct Picks | D20: H2H Opp | E20: Opp Picks | F20: H2H Result | G20: H2H Pts | H20: Pick Pts | I20: Week Total
A21: 1 | B21: =Roster!B3 -> Evan Loeser | C21: =SUMPRODUCT(('Picks Detail'!F25:F40<>"")*('Picks Detail'!E25:E40<>"")*('Picks Detail'!F25:F40='Picks Detail'!E25:E40)) -> 8 | D21: 6 | E21: =IFERROR(INDEX(C$21:C$32,MATCH(6,A$21:A$32,0)),0) -> 7 | F21: =IF(C21=0,"-",IF(C21>E21,"W",IF(C21<E21,"L",IF(AND('Picks Detail'!E41<>"",INDEX('Picks Detail'!F41:Q41,1,A21)<>"",INDEX('Picks Detail'!F41:Q41,1,D21)<>""),IF(ABS(INDEX('Picks Detail'!F41:Q41,1,A21)-'Picks Detail'!E41)<ABS(INDEX('Picks Detail'!F41:Q41,1,D21)-'Picks Detail'!E41),"W",IF(ABS(INDEX('Picks Detail'!F41:Q41,1,A21)-'Picks Detail'!E41)>ABS(INDEX('Picks Detail'!F41:Q41,1,D21)-'Picks Detail'!E41),"L","T")),"T")))) -> W | G21: =IF(F21="W",6,IF(F21="T",3,0)) -> 6 | H21: =IF(C21="",0,C21) -> 8 | I21: =G21+H21 -> 14
A22: 2 | B22: =Roster!B4 -> Chris Simmons | C22: =SUMPRODUCT(('Picks Detail'!G25:G40<>"")*('Picks Detail'!E25:E40<>"")*('Picks Detail'!G25:G40='Picks Detail'!E25:E40)) -> 8 | D22: 5 | E22: =IFERROR(INDEX(C$21:C$32,MATCH(5,A$21:A$32,0)),0) -> 6 | F22: =IF(C22=0,"-",IF(C22>E22,"W",IF(C22<E22,"L",IF(AND('Picks Detail'!E41<>"",INDEX('Picks Detail'!F41:Q41,1,A22)<>"",INDEX('Picks Detail'!F41:Q41,1,D22)<>""),IF(ABS(INDEX('Picks Detail'!F41:Q41,1,A22)-'Picks Detail'!E41)<ABS(INDEX('Picks Detail'!F41:Q41,1,D22)-'Picks Detail'!E41),"W",IF(ABS(INDEX('Picks Detail'!F41:Q41,1,A22)-'Picks Detail'!E41)>ABS(INDEX('Picks Detail'!F41:Q41,1,D22)-'Picks Detail'!E41),"L","T")),"T")))) -> W | G22: =IF(F22="W",6,IF(F22="T",3,0)) -> 6 | H22: =IF(C22="",0,C22) -> 8 | I22: =G22+H22 -> 14
A23: 3 | B23: =Roster!B5 -> Jack Smith | C23: =SUMPRODUCT(('Picks Detail'!H25:H40<>"")*('Picks Detail'!E25:E40<>"")*('Picks Detail'!H25:H40='Picks Detail'!E25:E40)) -> 6 | D23: 10 | E23: =IFERROR(INDEX(C$21:C$32,MATCH(10,A$21:A$32,0)),0) -> 8 | F23: =IF(C23=0,"-",IF(C23>E23,"W",IF(C23<E23,"L",IF(AND('Picks Detail'!E41<>"",INDEX('Picks Detail'!F41:Q41,1,A23)<>"",INDEX('Picks Detail'!F41:Q41,1,D23)<>""),IF(ABS(INDEX('Picks Detail'!F41:Q41,1,A23)-'Picks Detail'!E41)<ABS(INDEX('Picks Detail'!F41:Q41,1,D23)-'Picks Detail'!E41),"W",IF(ABS(INDEX('Picks Detail'!F41:Q41,1,A23)-'Picks Detail'!E41)>ABS(INDEX('Picks Detail'!F41:Q41,1,D23)-'Picks Detail'!E41),"L","T")),"T")))) -> L | G23: =IF(F23="W",6,IF(F23="T",3,0)) -> 0 | H23: =IF(C23="",0,C23) -> 6 | I23: =G23+H23 -> 6
A24: 4 | B24: =Roster!B6 -> Luke Ussery | C24: =SUMPRODUCT(('Picks Detail'!I25:I40<>"")*('Picks Detail'!E25:E40<>"")*('Picks Detail'!I25:I40='Picks Detail'!E25:E40)) -> 8 | D24: 9 | E24: =IFERROR(INDEX(C$21:C$32,MATCH(9,A$21:A$32,0)),0) -> 7 | F24: =IF(C24=0,"-",IF(C24>E24,"W",IF(C24<E24,"L",IF(AND('Picks Detail'!E41<>"",INDEX('Picks Detail'!F41:Q41,1,A24)<>"",INDEX('Picks Detail'!F41:Q41,1,D24)<>""),IF(ABS(INDEX('Picks Detail'!F41:Q41,1,A24)-'Picks Detail'!E41)<ABS(INDEX('Picks Detail'!F41:Q41,1,D24)-'Picks Detail'!E41),"W",IF(ABS(INDEX('Picks Detail'!F41:Q41,1,A24)-'Picks Detail'!E41)>ABS(INDEX('Picks Detail'!F41:Q41,1,D24)-'Picks Detail'!E41),"L","T")),"T")))) -> W | G24: =IF(F24="W",6,IF(F24="T",3,0)) -> 6 | H24: =IF(C24="",0,C24) -> 8 | I24: =G24+H24 -> 14
A25: 5 | B25: =Roster!B7 -> Mikayla Simmons | C25: =SUMPRODUCT(('Picks Detail'!J25:J40<>"")*('Picks Detail'!E25:E40<>"")*('Picks Detail'!J25:J40='Picks Detail'!E25:E40)) -> 6 | D25: 2 | E25: =IFERROR(INDEX(C$21:C$32,MATCH(2,A$21:A$32,0)),0) -> 8 | F25: =IF(C25=0,"-",IF(C25>E25,"W",IF(C25<E25,"L",IF(AND('Picks Detail'!E41<>"",INDEX('Picks Detail'!F41:Q41,1,A25)<>"",INDEX('Picks Detail'!F41:Q41,1,D25)<>""),IF(ABS(INDEX('Picks Detail'!F41:Q41,1,A25)-'Picks Detail'!E41)<ABS(INDEX('Picks Detail'!F41:Q41,1,D25)-'Picks Detail'!E41),"W",IF(ABS(INDEX('Picks Detail'!F41:Q41,1,A25)-'Picks Detail'!E41)>ABS(INDEX('Picks Detail'!F41:Q41,1,D25)-'Picks Detail'!E41),"L","T")),"T")))) -> L | G25: =IF(F25="W",6,IF(F25="T",3,0)) -> 0 | H25: =IF(C25="",0,C25) -> 6 | I25: =G25+H25 -> 6
A26: 6 | B26: =Roster!B8 -> Alan Loeser | C26: =SUMPRODUCT(('Picks Detail'!K25:K40<>"")*('Picks Detail'!E25:E40<>"")*('Picks Detail'!K25:K40='Picks Detail'!E25:E40)) -> 7 | D26: 1 | E26: =IFERROR(INDEX(C$21:C$32,MATCH(1,A$21:A$32,0)),0) -> 8 | F26: =IF(C26=0,"-",IF(C26>E26,"W",IF(C26<E26,"L",IF(AND('Picks Detail'!E41<>"",INDEX('Picks Detail'!F41:Q41,1,A26)<>"",INDEX('Picks Detail'!F41:Q41,1,D26)<>""),IF(ABS(INDEX('Picks Detail'!F41:Q41,1,A26)-'Picks Detail'!E41)<ABS(INDEX('Picks Detail'!F41:Q41,1,D26)-'Picks Detail'!E41),"W",IF(ABS(INDEX('Picks Detail'!F41:Q41,1,A26)-'Picks Detail'!E41)>ABS(INDEX('Picks Detail'!F41:Q41,1,D26)-'Picks Detail'!E41),"L","T")),"T")))) -> L | G26: =IF(F26="W",6,IF(F26="T",3,0)) -> 0 | H26: =IF(C26="",0,C26) -> 7 | I26: =G26+H26 -> 7
A27: 7 | B27: =Roster!B9 -> Caleb Simmons | C27: =SUMPRODUCT(('Picks Detail'!L25:L40<>"")*('Picks Detail'!E25:E40<>"")*('Picks Detail'!L25:L40='Picks Detail'!E25:E40)) -> 6 | D27: 12 | E27: =IFERROR(INDEX(C$21:C$32,MATCH(12,A$21:A$32,0)),0) -> 4 | F27: =IF(C27=0,"-",IF(C27>E27,"W",IF(C27<E27,"L",IF(AND('Picks Detail'!E41<>"",INDEX('Picks Detail'!F41:Q41,1,A27)<>"",INDEX('Picks Detail'!F41:Q41,1,D27)<>""),IF(ABS(INDEX('Picks Detail'!F41:Q41,1,A27)-'Picks Detail'!E41)<ABS(INDEX('Picks Detail'!F41:Q41,1,D27)-'Picks Detail'!E41),"W",IF(ABS(INDEX('Picks Detail'!F41:Q41,1,A27)-'Picks Detail'!E41)>ABS(INDEX('Picks Detail'!F41:Q41,1,D27)-'Picks Detail'!E41),"L","T")),"T")))) -> W | G27: =IF(F27="W",6,IF(F27="T",3,0)) -> 6 | H27: =IF(C27="",0,C27) -> 6 | I27: =G27+H27 -> 12
A28: 8 | B28: =Roster!B10 -> Larry Loeser | C28: =SUMPRODUCT(('Picks Detail'!M25:M40<>"")*('Picks Detail'!E25:E40<>"")*('Picks Detail'!M25:M40='Picks Detail'!E25:E40)) -> 4 | D28: 11 | E28: =IFERROR(INDEX(C$21:C$32,MATCH(11,A$21:A$32,0)),0) -> 6 | F28: =IF(C28=0,"-",IF(C28>E28,"W",IF(C28<E28,"L",IF(AND('Picks Detail'!E41<>"",INDEX('Picks Detail'!F41:Q41,1,A28)<>"",INDEX('Picks Detail'!F41:Q41,1,D28)<>""),IF(ABS(INDEX('Picks Detail'!F41:Q41,1,A28)-'Picks Detail'!E41)<ABS(INDEX('Picks Detail'!F41:Q41,1,D28)-'Picks Detail'!E41),"W",IF(ABS(INDEX('Picks Detail'!F41:Q41,1,A28)-'Picks Detail'!E41)>ABS(INDEX('Picks Detail'!F41:Q41,1,D28)-'Picks Detail'!E41),"L","T")),"T")))) -> L | G28: =IF(F28="W",6,IF(F28="T",3,0)) -> 0 | H28: =IF(C28="",0,C28) -> 4 | I28: =G28+H28 -> 4
A29: 9 | B29: =Roster!B11 -> Daddy Michael | C29: =SUMPRODUCT(('Picks Detail'!N25:N40<>"")*('Picks Detail'!E25:E40<>"")*('Picks Detail'!N25:N40='Picks Detail'!E25:E40)) -> 7 | D29: 4 | E29: =IFERROR(INDEX(C$21:C$32,MATCH(4,A$21:A$32,0)),0) -> 8 | F29: =IF(C29=0,"-",IF(C29>E29,"W",IF(C29<E29,"L",IF(AND('Picks Detail'!E41<>"",INDEX('Picks Detail'!F41:Q41,1,A29)<>"",INDEX('Picks Detail'!F41:Q41,1,D29)<>""),IF(ABS(INDEX('Picks Detail'!F41:Q41,1,A29)-'Picks Detail'!E41)<ABS(INDEX('Picks Detail'!F41:Q41,1,D29)-'Picks Detail'!E41),"W",IF(ABS(INDEX('Picks Detail'!F41:Q41,1,A29)-'Picks Detail'!E41)>ABS(INDEX('Picks Detail'!F41:Q41,1,D29)-'Picks Detail'!E41),"L","T")),"T")))) -> L | G29: =IF(F29="W",6,IF(F29="T",3,0)) -> 0 | H29: =IF(C29="",0,C29) -> 7 | I29: =G29+H29 -> 7
A30: 10 | B30: =Roster!B12 -> Zach Zarra | C30: =SUMPRODUCT(('Picks Detail'!O25:O40<>"")*('Picks Detail'!E25:E40<>"")*('Picks Detail'!O25:O40='Picks Detail'!E25:E40)) -> 8 | D30: 3 | E30: =IFERROR(INDEX(C$21:C$32,MATCH(3,A$21:A$32,0)),0) -> 6 | F30: =IF(C30=0,"-",IF(C30>E30,"W",IF(C30<E30,"L",IF(AND('Picks Detail'!E41<>"",INDEX('Picks Detail'!F41:Q41,1,A30)<>"",INDEX('Picks Detail'!F41:Q41,1,D30)<>""),IF(ABS(INDEX('Picks Detail'!F41:Q41,1,A30)-'Picks Detail'!E41)<ABS(INDEX('Picks Detail'!F41:Q41,1,D30)-'Picks Detail'!E41),"W",IF(ABS(INDEX('Picks Detail'!F41:Q41,1,A30)-'Picks Detail'!E41)>ABS(INDEX('Picks Detail'!F41:Q41,1,D30)-'Picks Detail'!E41),"L","T")),"T")))) -> W | G30: =IF(F30="W",6,IF(F30="T",3,0)) -> 6 | H30: =IF(C30="",0,C30) -> 8 | I30: =G30+H30 -> 14
A31: 11 | B31: =Roster!B13 -> Jeffrey Loeser | C31: =SUMPRODUCT(('Picks Detail'!P25:P40<>"")*('Picks Detail'!E25:E40<>"")*('Picks Detail'!P25:P40='Picks Detail'!E25:E40)) -> 6 | D31: 8 | E31: =IFERROR(INDEX(C$21:C$32,MATCH(8,A$21:A$32,0)),0) -> 4 | F31: =IF(C31=0,"-",IF(C31>E31,"W",IF(C31<E31,"L",IF(AND('Picks Detail'!E41<>"",INDEX('Picks Detail'!F41:Q41,1,A31)<>"",INDEX('Picks Detail'!F41:Q41,1,D31)<>""),IF(ABS(INDEX('Picks Detail'!F41:Q41,1,A31)-'Picks Detail'!E41)<ABS(INDEX('Picks Detail'!F41:Q41,1,D31)-'Picks Detail'!E41),"W",IF(ABS(INDEX('Picks Detail'!F41:Q41,1,A31)-'Picks Detail'!E41)>ABS(INDEX('Picks Detail'!F41:Q41,1,D31)-'Picks Detail'!E41),"L","T")),"T")))) -> W | G31: =IF(F31="W",6,IF(F31="T",3,0)) -> 6 | H31: =IF(C31="",0,C31) -> 6 | I31: =G31+H31 -> 12
A32: 12 | B32: =Roster!B14 -> Jake Andrews | C32: =SUMPRODUCT(('Picks Detail'!Q25:Q40<>"")*('Picks Detail'!E25:E40<>"")*('Picks Detail'!Q25:Q40='Picks Detail'!E25:E40)) -> 4 | D32: 7 | E32: =IFERROR(INDEX(C$21:C$32,MATCH(7,A$21:A$32,0)),0) -> 6 | F32: =IF(C32=0,"-",IF(C32>E32,"W",IF(C32<E32,"L",IF(AND('Picks Detail'!E41<>"",INDEX('Picks Detail'!F41:Q41,1,A32)<>"",INDEX('Picks Detail'!F41:Q41,1,D32)<>""),IF(ABS(INDEX('Picks Detail'!F41:Q41,1,A32)-'Picks Detail'!E41)<ABS(INDEX('Picks Detail'!F41:Q41,1,D32)-'Picks Detail'!E41),"W",IF(ABS(INDEX('Picks Detail'!F41:Q41,1,A32)-'Picks Detail'!E41)>ABS(INDEX('Picks Detail'!F41:Q41,1,D32)-'Picks Detail'!E41),"L","T")),"T")))) -> L | G32: =IF(F32="W",6,IF(F32="T",3,0)) -> 0 | H32: =IF(C32="",0,C32) -> 4 | I32: =G32+H32 -> 4
A34: WEEK 3
A35: Player # | B35: Player Name | C35: Correct Picks | D35: H2H Opp | E35: Opp Picks | F35: H2H Result | G35: H2H Pts | H35: Pick Pts | I35: Week Total
A36: 1 | B36: =Roster!B3 -> Evan Loeser | C36: =SUMPRODUCT(('Picks Detail'!F44:F59<>"")*('Picks Detail'!E44:E59<>"")*('Picks Detail'!F44:F59='Picks Detail'!E44:E59)) -> 12 | D36: 7 | E36: =IFERROR(INDEX(C$36:C$47,MATCH(7,A$36:A$47,0)),0) -> 8 | F36: =IF(C36=0,"-",IF(C36>E36,"W",IF(C36<E36,"L",IF(AND('Picks Detail'!E60<>"",INDEX('Picks Detail'!F60:Q60,1,A36)<>"",INDEX('Picks Detail'!F60:Q60,1,D36)<>""),IF(ABS(INDEX('Picks Detail'!F60:Q60,1,A36)-'Picks Detail'!E60)<ABS(INDEX('Picks Detail'!F60:Q60,1,D36)-'Picks Detail'!E60),"W",IF(ABS(INDEX('Picks Detail'!F60:Q60,1,A36)-'Picks Detail'!E60)>ABS(INDEX('Picks Detail'!F60:Q60,1,D36)-'Picks Detail'!E60),"L","T")),"T")))) -> W | G36: =IF(F36="W",6,IF(F36="T",3,0)) -> 6 | H36: =IF(C36="",0,C36) -> 12 | I36: =G36+H36 -> 18
A37: 2 | B37: =Roster!B4 -> Chris Simmons | C37: =SUMPRODUCT(('Picks Detail'!G44:G59<>"")*('Picks Detail'!E44:E59<>"")*('Picks Detail'!G44:G59='Picks Detail'!E44:E59)) -> 8 | D37: 8 | E37: =IFERROR(INDEX(C$36:C$47,MATCH(8,A$36:A$47,0)),0) -> 7 | F37: =IF(C37=0,"-",IF(C37>E37,"W",IF(C37<E37,"L",IF(AND('Picks Detail'!E60<>"",INDEX('Picks Detail'!F60:Q60,1,A37)<>"",INDEX('Picks Detail'!F60:Q60,1,D37)<>""),IF(ABS(INDEX('Picks Detail'!F60:Q60,1,A37)-'Picks Detail'!E60)<ABS(INDEX('Picks Detail'!F60:Q60,1,D37)-'Picks Detail'!E60),"W",IF(ABS(INDEX('Picks Detail'!F60:Q60,1,A37)-'Picks Detail'!E60)>ABS(INDEX('Picks Detail'!F60:Q60,1,D37)-'Picks Detail'!E60),"L","T")),"T")))) -> W | G37: =IF(F37="W",6,IF(F37="T",3,0)) -> 6 | H37: =IF(C37="",0,C37) -> 8 | I37: =G37+H37 -> 14
A38: 3 | B38: =Roster!B5 -> Jack Smith | C38: =SUMPRODUCT(('Picks Detail'!H44:H59<>"")*('Picks Detail'!E44:E59<>"")*('Picks Detail'!H44:H59='Picks Detail'!E44:E59)) -> 8 | D38: 11 | E38: =IFERROR(INDEX(C$36:C$47,MATCH(11,A$36:A$47,0)),0) -> 8 | F38: =IF(C38=0,"-",IF(C38>E38,"W",IF(C38<E38,"L",IF(AND('Picks Detail'!E60<>"",INDEX('Picks Detail'!F60:Q60,1,A38)<>"",INDEX('Picks Detail'!F60:Q60,1,D38)<>""),IF(ABS(INDEX('Picks Detail'!F60:Q60,1,A38)-'Picks Detail'!E60)<ABS(INDEX('Picks Detail'!F60:Q60,1,D38)-'Picks Detail'!E60),"W",IF(ABS(INDEX('Picks Detail'!F60:Q60,1,A38)-'Picks Detail'!E60)>ABS(INDEX('Picks Detail'!F60:Q60,1,D38)-'Picks Detail'!E60),"L","T")),"T")))) -> W | G38: =IF(F38="W",6,IF(F38="T",3,0)) -> 6 | H38: =IF(C38="",0,C38) -> 8 | I38: =G38+H38 -> 14
A39: 4 | B39: =Roster!B6 -> Luke Ussery | C39: =SUMPRODUCT(('Picks Detail'!I44:I59<>"")*('Picks Detail'!E44:E59<>"")*('Picks Detail'!I44:I59='Picks Detail'!E44:E59)) -> 0 | D39: 12 | E39: =IFERROR(INDEX(C$36:C$47,MATCH(12,A$36:A$47,0)),0) -> 6 | F39: =IF(C39=0,"-",IF(C39>E39,"W",IF(C39<E39,"L",IF(AND('Picks Detail'!E60<>"",INDEX('Picks Detail'!F60:Q60,1,A39)<>"",INDEX('Picks Detail'!F60:Q60,1,D39)<>""),IF(ABS(INDEX('Picks Detail'!F60:Q60,1,A39)-'Picks Detail'!E60)<ABS(INDEX('Picks Detail'!F60:Q60,1,D39)-'Picks Detail'!E60),"W",IF(ABS(INDEX('Picks Detail'!F60:Q60,1,A39)-'Picks Detail'!E60)>ABS(INDEX('Picks Detail'!F60:Q60,1,D39)-'Picks Detail'!E60),"L","T")),"T")))) -> - | G39: =IF(F39="W",6,IF(F39="T",3,0)) -> 0 | H39: =IF(C39="",0,C39) -> 0 | I39: =G39+H39 -> 0
A40: 5 | B40: =Roster!B7 -> Mikayla Simmons | C40: =SUMPRODUCT(('Picks Detail'!J44:J59<>"")*('Picks Detail'!E44:E59<>"")*('Picks Detail'!J44:J59='Picks Detail'!E44:E59)) -> 9 | D40: 9 | E40: =IFERROR(INDEX(C$36:C$47,MATCH(9,A$36:A$47,0)),0) -> 8 | F40: =IF(C40=0,"-",IF(C40>E40,"W",IF(C40<E40,"L",IF(AND('Picks Detail'!E60<>"",INDEX('Picks Detail'!F60:Q60,1,A40)<>"",INDEX('Picks Detail'!F60:Q60,1,D40)<>""),IF(ABS(INDEX('Picks Detail'!F60:Q60,1,A40)-'Picks Detail'!E60)<ABS(INDEX('Picks Detail'!F60:Q60,1,D40)-'Picks Detail'!E60),"W",IF(ABS(INDEX('Picks Detail'!F60:Q60,1,A40)-'Picks Detail'!E60)>ABS(INDEX('Picks Detail'!F60:Q60,1,D40)-'Picks Detail'!E60),"L","T")),"T")))) -> W | G40: =IF(F40="W",6,IF(F40="T",3,0)) -> 6 | H40: =IF(C40="",0,C40) -> 9 | I40: =G40+H40 -> 15
A41: 6 | B41: =Roster!B8 -> Alan Loeser | C41: =SUMPRODUCT(('Picks Detail'!K44:K59<>"")*('Picks Detail'!E44:E59<>"")*('Picks Detail'!K44:K59='Picks Detail'!E44:E59)) -> 7 | D41: 10 | E41: =IFERROR(INDEX(C$36:C$47,MATCH(10,A$36:A$47,0)),0) -> 5 | F41: =IF(C41=0,"-",IF(C41>E41,"W",IF(C41<E41,"L",IF(AND('Picks Detail'!E60<>"",INDEX('Picks Detail'!F60:Q60,1,A41)<>"",INDEX('Picks Detail'!F60:Q60,1,D41)<>""),IF(ABS(INDEX('Picks Detail'!F60:Q60,1,A41)-'Picks Detail'!E60)<ABS(INDEX('Picks Detail'!F60:Q60,1,D41)-'Picks Detail'!E60),"W",IF(ABS(INDEX('Picks Detail'!F60:Q60,1,A41)-'Picks Detail'!E60)>ABS(INDEX('Picks Detail'!F60:Q60,1,D41)-'Picks Detail'!E60),"L","T")),"T")))) -> W | G41: =IF(F41="W",6,IF(F41="T",3,0)) -> 6 | H41: =IF(C41="",0,C41) -> 7 | I41: =G41+H41 -> 13
A42: 7 | B42: =Roster!B9 -> Caleb Simmons | C42: =SUMPRODUCT(('Picks Detail'!L44:L59<>"")*('Picks Detail'!E44:E59<>"")*('Picks Detail'!L44:L59='Picks Detail'!E44:E59)) -> 8 | D42: 1 | E42: =IFERROR(INDEX(C$36:C$47,MATCH(1,A$36:A$47,0)),0) -> 12 | F42: =IF(C42=0,"-",IF(C42>E42,"W",IF(C42<E42,"L",IF(AND('Picks Detail'!E60<>"",INDEX('Picks Detail'!F60:Q60,1,A42)<>"",INDEX('Picks Detail'!F60:Q60,1,D42)<>""),IF(ABS(INDEX('Picks Detail'!F60:Q60,1,A42)-'Picks Detail'!E60)<ABS(INDEX('Picks Detail'!F60:Q60,1,D42)-'Picks Detail'!E60),"W",IF(ABS(INDEX('Picks Detail'!F60:Q60,1,A42)-'Picks Detail'!E60)>ABS(INDEX('Picks Detail'!F60:Q60,1,D42)-'Picks Detail'!E60),"L","T")),"T")))) -> L | G42: =IF(F42="W",6,IF(F42="T",3,0)) -> 0 | H42: =IF(C42="",0,C42) -> 8 | I42: =G42+H42 -> 8
A43: 8 | B43: =Roster!B10 -> Larry Loeser | C43: =SUMPRODUCT(('Picks Detail'!M44:M59<>"")*('Picks Detail'!E44:E59<>"")*('Picks Detail'!M44:M59='Picks Detail'!E44:E59)) -> 7 | D43: 2 | E43: =IFERROR(INDEX(C$36:C$47,MATCH(2,A$36:A$47,0)),0) -> 8 | F43: =IF(C43=0,"-",IF(C43>E43,"W",IF(C43<E43,"L",IF(AND('Picks Detail'!E60<>"",INDEX('Picks Detail'!F60:Q60,1,A43)<>"",INDEX('Picks Detail'!F60:Q60,1,D43)<>""),IF(ABS(INDEX('Picks Detail'!F60:Q60,1,A43)-'Picks Detail'!E60)<ABS(INDEX('Picks Detail'!F60:Q60,1,D43)-'Picks Detail'!E60),"W",IF(ABS(INDEX('Picks Detail'!F60:Q60,1,A43)-'Picks Detail'!E60)>ABS(INDEX('Picks Detail'!F60:Q60,1,D43)-'Picks Detail'!E60),"L","T")),"T")))) -> L | G43: =IF(F43="W",6,IF(F43="T",3,0)) -> 0 | H43: =IF(C43="",0,C43) -> 7 | I43: =G43+H43 -> 7
...

Sheet Wk 7-12 Input
A1: WEEKS 7-12 — WEEKLY INPUT
A2: Weighted points auto-calculated from Picks Detail (pick × point value). H2H auto-calculated.
A4: WEEK 7
A5: Player # | B5: Player Name | C5: Weighted Pts | D5: H2H Opp | E5: Opp Wtd Pts | F5: H2H Result | G5: H2H Pts | H5: Pick Pts | I5: Week Total
A6: 1 | B6: =Roster!B3 -> Evan Loeser | C6: =SUMPRODUCT(('Picks Detail'!F117:F130<>"")*('Picks Detail'!E117:E130<>"")*('Picks Detail'!F117:F130='Picks Detail'!E117:E130)*('Picks Detail'!S117:S130)) -> 0 | D6: 10 | E6: =IFERROR(INDEX(C$6:C$17,MATCH(10,A$6:A$17,0)),0) -> 0 | F6: =IF(C6=0,"-",IF(C6>E6,"W",IF(C6<E6,"L",IF(AND('Picks Detail'!E131<>"",INDEX('Picks Detail'!F131:Q131,1,A6)<>"",INDEX('Picks Detail'!F131:Q131,1,D6)<>""),IF(ABS(INDEX('Picks Detail'!F131:Q131,1,A6)-'Picks Detail'!E131)<ABS(INDEX('Picks Detail'!F131:Q131,1,D6)-'Picks Detail'!E131),"W",IF(ABS(INDEX('Picks Detail'!F131:Q131,1,A6)-'Picks Detail'!E131)>ABS(INDEX('Picks Detail'!F131:Q131,1,D6)-'Picks Detail'!E131),"L","T")),"T")))) -> - | G6: =IF(F6="W",10,IF(F6="T",5,0)) -> 0 | H6: =IF(C6="",0,C6) -> 0 | I6: =G6+H6 -> 0
A7: 2 | B7: =Roster!B4 -> Chris Simmons | C7: =SUMPRODUCT(('Picks Detail'!G117:G130<>"")*('Picks Detail'!E117:E130<>"")*('Picks Detail'!G117:G130='Picks Detail'!E117:E130)*('Picks Detail'!T117:T130)) -> 0 | D7: 9 | E7: =IFERROR(INDEX(C$6:C$17,MATCH(9,A$6:A$17,0)),0) -> 0 | F7: =IF(C7=0,"-",IF(C7>E7,"W",IF(C7<E7,"L",IF(AND('Picks Detail'!E131<>"",INDEX('Picks Detail'!F131:Q131,1,A7)<>"",INDEX('Picks Detail'!F131:Q131,1,D7)<>""),IF(ABS(INDEX('Picks Detail'!F131:Q131,1,A7)-'Picks Detail'!E131)<ABS(INDEX('Picks Detail'!F131:Q131,1,D7)-'Picks Detail'!E131),"W",IF(ABS(INDEX('Picks Detail'!F131:Q131,1,A7)-'Picks Detail'!E131)>ABS(INDEX('Picks Detail'!F131:Q131,1,D7)-'Picks Detail'!E131),"L","T")),"T")))) -> - | G7: =IF(F7="W",10,IF(F7="T",5,0)) -> 0 | H7: =IF(C7="",0,C7) -> 0 | I7: =G7+H7 -> 0
A8: 3 | B8: =Roster!B5 -> Jack Smith | C8: =SUMPRODUCT(('Picks Detail'!H117:H130<>"")*('Picks Detail'!E117:E130<>"")*('Picks Detail'!H117:H130='Picks Detail'!E117:E130)*('Picks Detail'!U117:U130)) -> 0 | D8: 8 | E8: =IFERROR(INDEX(C$6:C$17,MATCH(8,A$6:A$17,0)),0) -> 0 | F8: =IF(C8=0,"-",IF(C8>E8,"W",IF(C8<E8,"L",IF(AND('Picks Detail'!E131<>"",INDEX('Picks Detail'!F131:Q131,1,A8)<>"",INDEX('Picks Detail'!F131:Q131,1,D8)<>""),IF(ABS(INDEX('Picks Detail'!F131:Q131,1,A8)-'Picks Detail'!E131)<ABS(INDEX('Picks Detail'!F131:Q131,1,D8)-'Picks Detail'!E131),"W",IF(ABS(INDEX('Picks Detail'!F131:Q131,1,A8)-'Picks Detail'!E131)>ABS(INDEX('Picks Detail'!F131:Q131,1,D8)-'Picks Detail'!E131),"L","T")),"T")))) -> - | G8: =IF(F8="W",10,IF(F8="T",5,0)) -> 0 | H8: =IF(C8="",0,C8) -> 0 | I8: =G8+H8 -> 0
A9: 4 | B9: =Roster!B6 -> Luke Ussery | C9: =SUMPRODUCT(('Picks Detail'!I117:I130<>"")*('Picks Detail'!E117:E130<>"")*('Picks Detail'!I117:I130='Picks Detail'!E117:E130)*('Picks Detail'!V117:V130)) -> 0 | D9: 7 | E9: =IFERROR(INDEX(C$6:C$17,MATCH(7,A$6:A$17,0)),0) -> 0 | F9: =IF(C9=0,"-",IF(C9>E9,"W",IF(C9<E9,"L",IF(AND('Picks Detail'!E131<>"",INDEX('Picks Detail'!F131:Q131,1,A9)<>"",INDEX('Picks Detail'!F131:Q131,1,D9)<>""),IF(ABS(INDEX('Picks Detail'!F131:Q131,1,A9)-'Picks Detail'!E131)<ABS(INDEX('Picks Detail'!F131:Q131,1,D9)-'Picks Detail'!E131),"W",IF(ABS(INDEX('Picks Detail'!F131:Q131,1,A9)-'Picks Detail'!E131)>ABS(INDEX('Picks Detail'!F131:Q131,1,D9)-'Picks Detail'!E131),"L","T")),"T")))) -> - | G9: =IF(F9="W",10,IF(F9="T",5,0)) -> 0 | H9: =IF(C9="",0,C9) -> 0 | I9: =G9+H9 -> 0
A10: 5 | B10: =Roster!B7 -> Mikayla Simmons | C10: =SUMPRODUCT(('Picks Detail'!J117:J130<>"")*('Picks Detail'!E117:E130<>"")*('Picks Detail'!J117:J130='Picks Detail'!E117:E130)*('Picks Detail'!W117:W130)) -> 0 | D10: 11 | E10: =IFERROR(INDEX(C$6:C$17,MATCH(11,A$6:A$17,0)),0) -> 0 | F10: =IF(C10=0,"-",IF(C10>E10,"W",IF(C10<E10,"L",IF(AND('Picks Detail'!E131<>"",INDEX('Picks Detail'!F131:Q131,1,A10)<>"",INDEX('Picks Detail'!F131:Q131,1,D10)<>""),IF(ABS(INDEX('Picks Detail'!F131:Q131,1,A10)-'Picks Detail'!E131)<ABS(INDEX('Picks Detail'!F131:Q131,1,D10)-'Picks Detail'!E131),"W",IF(ABS(INDEX('Picks Detail'!F131:Q131,1,A10)-'Picks Detail'!E131)>ABS(INDEX('Picks Detail'!F131:Q131,1,D10)-'Picks Detail'!E131),"L","T")),"T")))) -> - | G10: =IF(F10="W",10,IF(F10="T",5,0)) -> 0 | H10: =IF(C10="",0,C10) -> 0 | I10: =G10+H10 -> 0
A11: 6 | B11: =Roster!B8 -> Alan Loeser | C11: =SUMPRODUCT(('Picks Detail'!K117:K130<>"")*('Picks Detail'!E117:E130<>"")*('Picks Detail'!K117:K130='Picks Detail'!E117:E130)*('Picks Detail'!X117:X130)) -> 0 | D11: 12 | E11: =IFERROR(INDEX(C$6:C$17,MATCH(12,A$6:A$17,0)),0) -> 0 | F11: =IF(C11=0,"-",IF(C11>E11,"W",IF(C11<E11,"L",IF(AND('Picks Detail'!E131<>"",INDEX('Picks Detail'!F131:Q131,1,A11)<>"",INDEX('Picks Detail'!F131:Q131,1,D11)<>""),IF(ABS(INDEX('Picks Detail'!F131:Q131,1,A11)-'Picks Detail'!E131)<ABS(INDEX('Picks Detail'!F131:Q131,1,D11)-'Picks Detail'!E131),"W",IF(ABS(INDEX('Picks Detail'!F131:Q131,1,A11)-'Picks Detail'!E131)>ABS(INDEX('Picks Detail'!F131:Q131,1,D11)-'Picks Detail'!E131),"L","T")),"T")))) -> - | G11: =IF(F11="W",10,IF(F11="T",5,0)) -> 0 | H11: =IF(C11="",0,C11) -> 0 | I11: =G11+H11 -> 0
A12: 7 | B12: =Roster!B9 -> Caleb Simmons | C12: =SUMPRODUCT(('Picks Detail'!L117:L130<>"")*('Picks Detail'!E117:E130<>"")*('Picks Detail'!L117:L130='Picks Detail'!E117:E130)*('Picks Detail'!Y117:Y130)) -> 0 | D12: 4 | E12: =IFERROR(INDEX(C$6:C$17,MATCH(4,A$6:A$17,0)),0) -> 0 | F12: =IF(C12=0,"-",IF(C12>E12,"W",IF(C12<E12,"L",IF(AND('Picks Detail'!E131<>"",INDEX('Picks Detail'!F131:Q131,1,A12)<>"",INDEX('Picks Detail'!F131:Q131,1,D12)<>""),IF(ABS(INDEX('Picks Detail'!F131:Q131,1,A12)-'Picks Detail'!E131)<ABS(INDEX('Picks Detail'!F131:Q131,1,D12)-'Picks Detail'!E131),"W",IF(ABS(INDEX('Picks Detail'!F131:Q131,1,A12)-'Picks Detail'!E131)>ABS(INDEX('Picks Detail'!F131:Q131,1,D12)-'Picks Detail'!E131),"L","T")),"T")))) -> - | G12: =IF(F12="W",10,IF(F12="T",5,0)) -> 0 | H12: =IF(C12="",0,C12) -> 0 | I12: =G12+H12 -> 0
A13: 8 | B13: =Roster!B10 -> Larry Loeser | C13: =SUMPRODUCT(('Picks Detail'!M117:M130<>"")*('Picks Detail'!E117:E130<>"")*('Picks Detail'!M117:M130='Picks Detail'!E117:E130)*('Picks Detail'!Z117:Z130)) -> 0 | D13: 3 | E13: =IFERROR(INDEX(C$6:C$17,MATCH(3,A$6:A$17,0)),0) -> 0 | F13: =IF(C13=0,"-",IF(C13>E13,"W",IF(C13<E13,"L",IF(AND('Picks Detail'!E131<>"",INDEX('Picks Detail'!F131:Q131,1,A13)<>"",INDEX('Picks Detail'!F131:Q131,1,D13)<>""),IF(ABS(INDEX('Picks Detail'!F131:Q131,1,A13)-'Picks Detail'!E131)<ABS(INDEX('Picks Detail'!F131:Q131,1,D13)-'Picks Detail'!E131),"W",IF(ABS(INDEX('Picks Detail'!F131:Q131,1,A13)-'Picks Detail'!E131)>ABS(INDEX('Picks Detail'!F131:Q131,1,D13)-'Picks Detail'!E131),"L","T")),"T")))) -> - | G13: =IF(F13="W",10,IF(F13="T",5,0)) -> 0 | H13: =IF(C13="",0,C13) -> 0 | I13: =G13+H13 -> 0
A14: 9 | B14: =Roster!B11 -> Daddy Michael | C14: =SUMPRODUCT(('Picks Detail'!N117:N130<>"")*('Picks Detail'!E117:E130<>"")*('Picks Detail'!N117:N130='Picks Detail'!E117:E130)*('Picks Detail'!AA117:AA130)) -> 0 | D14: 2 | E14: =IFERROR(INDEX(C$6:C$17,MATCH(2,A$6:A$17,0)),0) -> 0 | F14: =IF(C14=0,"-",IF(C14>E14,"W",IF(C14<E14,"L",IF(AND('Picks Detail'!E131<>"",INDEX('Picks Detail'!F131:Q131,1,A14)<>"",INDEX('Picks Detail'!F131:Q131,1,D14)<>""),IF(ABS(INDEX('Picks Detail'!F131:Q131,1,A14)-'Picks Detail'!E131)<ABS(INDEX('Picks Detail'!F131:Q131,1,D14)-'Picks Detail'!E131),"W",IF(ABS(INDEX('Picks Detail'!F131:Q131,1,A14)-'Picks Detail'!E131)>ABS(INDEX('Picks Detail'!F131:Q131,1,D14)-'Picks Detail'!E131),"L","T")),"T")))) -> - | G14: =IF(F14="W",10,IF(F14="T",5,0)) -> 0 | H14: =IF(C14="",0,C14) -> 0 | I14: =G14+H14 -> 0
A15: 10 | B15: =Roster!B12 -> Zach Zarra | C15: =SUMPRODUCT(('Picks Detail'!O117:O130<>"")*('Picks Detail'!E117:E130<>"")*('Picks Detail'!O117:O130='Picks Detail'!E117:E130)*('Picks Detail'!AB117:AB130)) -> 0 | D15: 1 | E15: =IFERROR(INDEX(C$6:C$17,MATCH(1,A$6:A$17,0)),0) -> 0 | F15: =IF(C15=0,"-",IF(C15>E15,"W",IF(C15<E15,"L",IF(AND('Picks Detail'!E131<>"",INDEX('Picks Detail'!F131:Q131,1,A15)<>"",INDEX('Picks Detail'!F131:Q131,1,D15)<>""),IF(ABS(INDEX('Picks Detail'!F131:Q131,1,A15)-'Picks Detail'!E131)<ABS(INDEX('Picks Detail'!F131:Q131,1,D15)-'Picks Detail'!E131),"W",IF(ABS(INDEX('Picks Detail'!F131:Q131,1,A15)-'Picks Detail'!E131)>ABS(INDEX('Picks Detail'!F131:Q131,1,D15)-'Picks Detail'!E131),"L","T")),"T")))) -> - | G15: =IF(F15="W",10,IF(F15="T",5,0)) -> 0 | H15: =IF(C15="",0,C15) -> 0 | I15: =G15+H15 -> 0
A16: 11 | B16: =Roster!B13 -> Jeffrey Loeser | C16: =SUMPRODUCT(('Picks Detail'!P117:P130<>"")*('Picks Detail'!E117:E130<>"")*('Picks Detail'!P117:P130='Picks Detail'!E117:E130)*('Picks Detail'!AC117:AC130)) -> 0 | D16: 5 | E16: =IFERROR(INDEX(C$6:C$17,MATCH(5,A$6:A$17,0)),0) -> 0 | F16: =IF(C16=0,"-",IF(C16>E16,"W",IF(C16<E16,"L",IF(AND('Picks Detail'!E131<>"",INDEX('Picks Detail'!F131:Q131,1,A16)<>"",INDEX('Picks Detail'!F131:Q131,1,D16)<>""),IF(ABS(INDEX('Picks Detail'!F131:Q131,1,A16)-'Picks Detail'!E131)<ABS(INDEX('Picks Detail'!F131:Q131,1,D16)-'Picks Detail'!E131),"W",IF(ABS(INDEX('Picks Detail'!F131:Q131,1,A16)-'Picks Detail'!E131)>ABS(INDEX('Picks Detail'!F131:Q131,1,D16)-'Picks Detail'!E131),"L","T")),"T")))) -> - | G16: =IF(F16="W",10,IF(F16="T",5,0)) -> 0 | H16: =IF(C16="",0,C16) -> 0 | I16: =G16+H16 -> 0
A17: 12 | B17: =Roster!B14 -> Jake Andrews | C17: =SUMPRODUCT(('Picks Detail'!Q117:Q130<>"")*('Picks Detail'!E117:E130<>"")*('Picks Detail'!Q117:Q130='Picks Detail'!E117:E130)*('Picks Detail'!AD117:AD130)) -> 0 | D17: 6 | E17: =IFERROR(INDEX(C$6:C$17,MATCH(6,A$6:A$17,0)),0) -> 0 | F17: =IF(C17=0,"-",IF(C17>E17,"W",IF(C17<E17,"L",IF(AND('Picks Detail'!E131<>"",INDEX('Picks Detail'!F131:Q131,1,A17)<>"",INDEX('Picks Detail'!F131:Q131,1,D17)<>""),IF(ABS(INDEX('Picks Detail'!F131:Q131,1,A17)-'Picks Detail'!E131)<ABS(INDEX('Picks Detail'!F131:Q131,1,D17)-'Picks Detail'!E131),"W",IF(ABS(INDEX('Picks Detail'!F131:Q131,1,A17)-'Picks Detail'!E131)>ABS(INDEX('Picks Detail'!F131:Q131,1,D17)-'Picks Detail'!E131),"L","T")),"T")))) -> - | G17: =IF(F17="W",10,IF(F17="T",5,0)) -> 0 | H17: =IF(C17="",0,C17) -> 0 | I17: =G17+H17 -> 0
A19: WEEK 8
A20: Player # | B20: Player Name | C20: Weighted Pts | D20: H2H Opp | E20: Opp Wtd Pts | F20: H2H Result | G20: H2H Pts | H20: Pick Pts | I20: Week Total
A21: 1 | B21: =Roster!B3 -> Evan Loeser | C21: =SUMPRODUCT(('Picks Detail'!F134:F147<>"")*('Picks Detail'!E134:E147<>"")*('Picks Detail'!F134:F147='Picks Detail'!E134:E147)*('Picks Detail'!S134:S147)) -> 0 | D21: 12 | E21: =IFERROR(INDEX(C$21:C$32,MATCH(12,A$21:A$32,0)),0) -> 0 | F21: =IF(C21=0,"-",IF(C21>E21,"W",IF(C21<E21,"L",IF(AND('Picks Detail'!E148<>"",INDEX('Picks Detail'!F148:Q148,1,A21)<>"",INDEX('Picks Detail'!F148:Q148,1,D21)<>""),IF(ABS(INDEX('Picks Detail'!F148:Q148,1,A21)-'Picks Detail'!E148)<ABS(INDEX('Picks Detail'!F148:Q148,1,D21)-'Picks Detail'!E148),"W",IF(ABS(INDEX('Picks Detail'!F148:Q148,1,A21)-'Picks Detail'!E148)>ABS(INDEX('Picks Detail'!F148:Q148,1,D21)-'Picks Detail'!E148),"L","T")),"T")))) -> - | G21: =IF(F21="W",10,IF(F21="T",5,0)) -> 0 | H21: =IF(C21="",0,C21) -> 0 | I21: =G21+H21 -> 0
A22: 2 | B22: =Roster!B4 -> Chris Simmons | C22: =SUMPRODUCT(('Picks Detail'!G134:G147<>"")*('Picks Detail'!E134:E147<>"")*('Picks Detail'!G134:G147='Picks Detail'!E134:E147)*('Picks Detail'!T134:T147)) -> 0 | D22: 11 | E22: =IFERROR(INDEX(C$21:C$32,MATCH(11,A$21:A$32,0)),0) -> 0 | F22: =IF(C22=0,"-",IF(C22>E22,"W",IF(C22<E22,"L",IF(AND('Picks Detail'!E148<>"",INDEX('Picks Detail'!F148:Q148,1,A22)<>"",INDEX('Picks Detail'!F148:Q148,1,D22)<>""),IF(ABS(INDEX('Picks Detail'!F148:Q148,1,A22)-'Picks Detail'!E148)<ABS(INDEX('Picks Detail'!F148:Q148,1,D22)-'Picks Detail'!E148),"W",IF(ABS(INDEX('Picks Detail'!F148:Q148,1,A22)-'Picks Detail'!E148)>ABS(INDEX('Picks Detail'!F148:Q148,1,D22)-'Picks Detail'!E148),"L","T")),"T")))) -> - | G22: =IF(F22="W",10,IF(F22="T",5,0)) -> 0 | H22: =IF(C22="",0,C22) -> 0 | I22: =G22+H22 -> 0
